Workbook

Sheet Dashboard
A1: GRAUWASSER · Bewertungsdashboard
A2: Dashboard | B2: Eingaben | C2: Profile | D2: Kalender | E2: Methodik
A3: Wissenschaftlicher Excel-Prototyp · makrofrei · Eingaben blau · Ampelschwellen vorläufig · keine Freigabe
A4: Projekt | C4: =Eingaben!$B$5 -> OGS mit Sporthalle – RECHENBEISPIEL | I4: ="Zeitraum: "&Eingaben!$B$11&" Jahre | Bilanz "&Eingaben!$B$10 -> Zeitraum: 20 Jahre | Bilanz 2026
A5: Gebäudetyp | C5: =Eingaben!$B$6 -> Offene Ganztagsschule mit Sporthalle | I5: =Berechnung!$B$41 -> Modellergebnis mit Beispieldaten
A7: Grauwasseranfall | D7: Betriebswasserbedarf | G7: Nutzbar / Trinkwasser gespart | J7: Trinkwassereinsparquote
A8: =IF(Berechnung!$B$5>0,"Eingaben prüfen",Berechnung!$B$6) -> 742.2 | D8: =IF(Berechnung!$B$5>0,"Eingaben prüfen",Berechnung!$B$9) -> 1018.7 | G8: =IF(Berechnung!$B$5>0,"Eingaben prüfen",Berechnung!$B$10) -> 555.38976 | J8: =IF(Berechnung!$B$5>0,"Eingaben prüfen",Berechnung!$B$22) -> 0.22050651
A11: Gesamtinvestition | D11: Betriebskosten Jahr 1 | G11: Vermiedene Kosten Jahr 1 | J11: Netto-Cashflow Jahr 1
A12: =IF(Berechnung!$B$5>0,"Eingaben prüfen",Berechnung!$B$13) -> 25000 | D12: =IF(Berechnung!$B$5>0,"Eingaben prüfen",Berechnung!$B$16) -> 781.527 | G12: =IF(Berechnung!$B$5>0,"Eingaben prüfen",Berechnung!$B$17) -> 1388.4744 | J12: =IF(Berechnung!$B$5>0,"Eingaben prüfen",Berechnung!$B$18) -> 606.94739
A15: Statische Amortisation | D15: Dynamische Amortisation | G15: Kapitalwert | J15: Deckungsgrad
A16: =IF(Berechnung!$B$5>0,"Eingaben prüfen",Berechnung!$B$19) -> 41.189731 | D16: =IF(Berechnung!$B$5>0,"Eingaben prüfen",Berechnung!$B$21) -> Im Zeitraum nicht erreicht | G16: =IF(Berechnung!$B$5>0,"Eingaben prüfen",Berechnung!$B$20) -> -17797.873 | J16: =IF(Berechnung!$B$5>0,"Eingaben prüfen",Berechnung!$B$23) -> 0.54519462
A19: Ökonomie | E19: Ressourcen | I19: Gesamtbewertung
A20: =Berechnung!$B$31 -> Rot | E20: =Berechnung!$B$32 -> Grün | I20: =Berechnung!$B$33 -> Rot
A21: =IF(Berechnung!$B$5>0,"Bewertung gesperrt: "&Berechnung!$B$5&" Pflichtfehler; Blatt Prüfungen öffnen.","Ökonomie: Kapitalwert "&TEXT(Berechnung!$B$20,"#,##0.00")&" €; Kriterium NPV/Nettoinvestition, Grün ab "&TEXT(Schwellenwerte!B5,"0.0%")&", Gelb ab "&TEXT(Schwellenwerte!B6,"0.0%")&". Ohne Nettoinvestition entscheidet Vorzeichen des NPV.") -> Ökonomie: Kapitalwert -17,797.87 €; Kriterium NPV/Nettoinvestition, Grün ab 0.0%, Gelb ab -20.0%. Ohne Nettoinvestition entscheidet Vorzeichen des NPV.
A22: =IF(Berechnung!$B$5>0,"Ressourcenbewertung gesperrt.","Ressourcen: Einsparquote "&TEXT(Berechnung!$B$22,"0.0%")&"; Grün ab "&TEXT(Schwellenwerte!B9,"0.0%")&", Gelb ab "&TEXT(Schwellenwerte!B10,"0.0%")&". Ohne Einsparung Rot. Keine vollständige Umweltbilanz.") -> Ressourcen: Einsparquote 22.1%; Grün ab 15.0%, Gelb ab 5.0%. Ohne Einsparung Rot. Keine vollständige Umweltbilanz.
A23: ="Gesamt = schlechteste Kategorie einschließlich Nachweisstatus. "&Berechnung!$B$34&". Statische Amortisation nur innerhalb Horizont interpretieren; dynamische Stabilität: "&Berechnung!$B$37&"." -> Gesamt = schlechteste Kategorie einschließlich Nachweisstatus. PRÜFBEDARF: Nachweise ungeklärt. Statische Amortisation nur innerhalb Horizont interpretieren; dynamische Stabilität: Keine positive Rückgewinnung.
A24: =Berechnung!$B$40 -> BEISPIELDATEN · PRÜFBEDARF: Nachweise ungeklärt · Statische Amortisation außerhalb Horizont. · Schwellen vorläufig; Tagesprofil und Quellen projektbezogen validieren.
P46: Wasserbilanz | Q46: m³/a
P47: Rohgrauwasser | Q47: =IF(Berechnung!$B$5=0,Berechnung!$B$6,0) -> 742.2
P48: Aufbereitet | Q48: =IF(Berechnung!$B$5=0,Berechnung!$B$8,0) -> 634.581
P49: Wiederverwendung | Q49: =IF(Berechnung!$B$5=0,Berechnung!$B$10,0) -> 555.38976
P50: Betriebsbedarf | Q50: =IF(Berechnung!$B$5=0,Berechnung!$B$9,0) -> 1018.7
P51: Nachspeisung | Q51: =IF(Berechnung!$B$5=0,Berechnung!$B$11,0) -> 463.31024
P54: Jahr | Q54: Cashflow € | R54: Kumuliert diskontiert €
P55: =IFERROR(MIN(Zahlungen!A7,Eingaben!$B$11),0) -> 0 | Q55: =IF(Berechnung!$B$5=0,INDEX(Zahlungen!$G$7:$G$57,P55+1),0) -> -25000 | R55: =IF(Berechnung!$B$5=0,INDEX(Zahlungen!$J$7:$J$57,P55+1),0) -> -25000
P56: =IFERROR(MIN(Zahlungen!A8,Eingaben!$B$11),0) -> 1 | Q56: =IF(Berechnung!$B$5=0,INDEX(Zahlungen!$G$7:$G$57,P56+1),0) -> 606.94739 | R56: =IF(Berechnung!$B$5=0,INDEX(Zahlungen!$J$7:$J$57,P56+1),0) -> -24410.731
P57: =IFERROR(MIN(Zahlungen!A9,Eingaben!$B$11),0) -> 2 | Q57: =IF(Berechnung!$B$5=0,INDEX(Zahlungen!$G$7:$G$57,P57+1),0) -> 619.08634 | R57: =IF(Berechnung!$B$5=0,INDEX(Zahlungen!$J$7:$J$57,P57+1),0) -> -23827.182
P58: =IFERROR(MIN(Zahlungen!A10,Eingaben!$B$11),0) -> 3 | Q58: =IF(Berechnung!$B$5=0,INDEX(Zahlungen!$G$7:$G$57,P58+1),0) -> 631.46807 | R58: =IF(Berechnung!$B$5=0,INDEX(Zahlungen!$J$7:$J$57,P58+1),0) -> -23249.3
P59: =IFERROR(MIN(Zahlungen!A11,Eingaben!$B$11),0) -> 4 | Q59: =IF(Berechnung!$B$5=0,INDEX(Zahlungen!$G$7:$G$57,P59+1),0) -> 644.09743 | R59: =IF(Berechnung!$B$5=0,INDEX(Zahlungen!$J$7:$J$57,P59+1),0) -> -22677.027
P60: =IFERROR(MIN(Zahlungen!A12,Eingaben!$B$11),0) -> 5 | Q60: =IF(Berechnung!$B$5=0,INDEX(Zahlungen!$G$7:$G$57,P60+1),0) -> 656.97938 | R60: =IF(Berechnung!$B$5=0,INDEX(Zahlungen!$J$7:$J$57,P60+1),0) -> -22110.311
P61: =IFERROR(MIN(Zahlungen!A13,Eingaben!$B$11),0) -> 6 | Q61: =IF(Berechnung!$B$5=0,INDEX(Zahlungen!$G$7:$G$57,P61+1),0) -> 670.11897 | R61: =IF(Berechnung!$B$5=0,INDEX(Zahlungen!$J$7:$J$57,P61+1),0) -> -21549.097
A62: Anleitung → Eingaben → Profile → Kalender → Nachweise → Dashboard → Szenarien. Tabellen rechts liefern Diagrammdaten. | P62: =IFERROR(MIN(Zahlungen!A14,Eingaben!$B$11),0) -> 7 | Q62: =IF(Berechnung!$B$5=0,INDEX(Zahlungen!$G$7:$G$57,P62+1),0) -> 683.52134 | R62: =IF(Berechnung!$B$5=0,INDEX(Zahlungen!$J$7:$J$57,P62+1),0) -> -20993.332
P63: =IFERROR(MIN(Zahlungen!A15,Eingaben!$B$11),0) -> 8 | Q63: =IF(Berechnung!$B$5=0,INDEX(Zahlungen!$G$7:$G$57,P63+1),0) -> 697.19177 | R63: =IF(Berechnung!$B$5=0,INDEX(Zahlungen!$J$7:$J$57,P63+1),0) -> -20442.962
P64: =IFERROR(MIN(Zahlungen!A16,Eingaben!$B$11),0) -> 9 | Q64: =IF(Berechnung!$B$5=0,INDEX(Zahlungen!$G$7:$G$57,P64+1),0) -> 711.13561 | R64: =IF(Berechnung!$B$5=0,INDEX(Zahlungen!$J$7:$J$57,P64+1),0) -> -19897.936
P65: =IFERROR(MIN(Zahlungen!A17,Eingaben!$B$11),0) -> 10 | Q65: =IF(Berechnung!$B$5=0,INDEX(Zahlungen!$G$7:$G$57,P65+1),0) -> -4055.012 | R65: =IF(Berechnung!$B$5=0,INDEX(Zahlungen!$J$7:$J$57,P65+1),0) -> -22915.246
P66: =IFERROR(MIN(Zahlungen!A18,Eingaben!$B$11),0) -> 11 | Q66: =IF(Berechnung!$B$5=0,INDEX(Zahlungen!$G$7:$G$57,P66+1),0) -> 739.86549 | R66: =IF(Berechnung!$B$5=0,INDEX(Zahlungen!$J$7:$J$57,P66+1),0) -> -22380.751
P67: =IFERROR(MIN(Zahlungen!A19,Eingaben!$B$11),0) -> 12 | Q67: =IF(Berechnung!$B$5=0,INDEX(Zahlungen!$G$7:$G$57,P67+1),0) -> 754.6628 | R67: =IF(Berechnung!$B$5=0,INDEX(Zahlungen!$J$7:$J$57,P67+1),0) -> -21851.446
P68: =IFERROR(MIN(Zahlungen!A20,Eingaben!$B$11),0) -> 13 | Q68: =IF(Berechnung!$B$5=0,INDEX(Zahlungen!$G$7:$G$57,P68+1),0) -> 769.75605 | R68: =IF(Berechnung!$B$5=0,INDEX(Zahlungen!$J$7:$J$57,P68+1),0) -> -21327.279
P69: =IFERROR(MIN(Zahlungen!A21,Eingaben!$B$11),0) -> 14 | Q69: =IF(Berechnung!$B$5=0,INDEX(Zahlungen!$G$7:$G$57,P69+1),0) -> 785.15117 | R69: =IF(Berechnung!$B$5=0,INDEX(Zahlungen!$J$7:$J$57,P69+1),0) -> -20808.202
P70: =IFERROR(MIN(Zahlungen!A22,Eingaben!$B$11),0) -> 15 | Q70: =IF(Berechnung!$B$5=0,INDEX(Zahlungen!$G$7:$G$57,P70+1),0) -> 800.8542 | R70: =IF(Berechnung!$B$5=0,INDEX(Zahlungen!$J$7:$J$57,P70+1),0) -> -20294.164
...

Sheet Eingaben
A1: Projekt & Anlage
A2: Dashboard | B2: Eingaben | C2: Profile | D2: Kalender | E2: Methodik
A3: Blaue Felder bearbeiten · RECHENBEISPIEL, nicht vermessene Projektwerte
A4: 01 Projekt
A5: Projektname | B5: OGS mit Sporthalle – RECHENBEISPIEL | C5: – | D5: Bezeichnung für Dashboard und Dokumentation.
A6: Gebäudetyp | B6: Offene Ganztagsschule mit Sporthalle | C6: – | D6: Nutzergruppen separat in Nutzungsprofile erfassen.
A7: Standort | B7: Beispielstandort – keine realen Projektdaten | C7: – | D7: Gebührenbescheid und tatsächlichen Ferienkalender prüfen.
A8: Geplante Anlage | B8: Modellanlage – Herstellerdaten ergänzen | C8: – | D8: Kapazität, Energie und Verluste mit Hersteller-/Messdaten belegen.
A9: Nutzer im Referenzprojekt | B9: 300 | C9: Personen | D9: Informative Bezugsgröße; Profile dürfen Teil-/Fremdnutzer abbilden.
A10: Bilanzjahr | B10: 2026 | C10: Jahr | D10: Bei Jahreswechsel Kalenderflaggen kontrollieren; keine automatische Ferienerkennung.
A11: Betrachtungszeitraum | B11: 20 | C11: Jahre | D11: 1–50; Kalenderjahr wird für alle Betriebsjahre wiederholt.
A12: Sonstiger Trinkwasserbedarf | B12: 1500 | C12: m³/a | D12: Baseline außerhalb erfasster Betriebswassernutzungen; keine Doppelzählung.
A14: 02 Anlage, Speicher & Nachweise
A15: Aufbereitungsausbeute | B15: 0.9 | C15: % | D15: Aufbereitet / verarbeitet. Kein garantierter Herstellerwert.
A16: Betriebsverfügbarkeit | B16: 0.95 | C16: % | D16: Pauschaler Tagesfaktor auf min(Rohwasser, Kapazität); kein Ausfallkalender.
A17: Rohwasser-Aufbereitungskapazität | B17: 5 | C17: m³/d | D17: Maximale verarbeitbare Rohwassermenge je Tag vor Verfügbarkeitsfaktor.
A18: Nutzbares Speichervolumen | B18: 2 | C18: m³ | D18: Modell: frischer Tagesrest für genau den Folgetag; alte Reste werden verworfen.
A19: Direkt nutzbarer Tagesanteil | B19: 0.7 | C19: % | D19: Vereinfachte zeitliche Übereinstimmung; mit Stundenprofilen validieren.
A20: Verlust bei Tagesübertrag | B20: 0.02 | C20: % | D20: Volumetrischer Verlust, keine hygienische Inaktivierungsrate.
A21: Hygienische Nachweise | B21: Ungeklärt | C21: Status | D21: Ungeklärt begrenzt Gesamtergebnis auf Gelb; Nicht erfüllt ergibt Rot.
A22: Technische Nachweise | B22: Ungeklärt | C22: Status | D22: Trennung, Nachspeisung, Betrieb und Auslegung projektbezogen prüfen.
A23: Rechtliche Zulässigkeit | B23: Ungeklärt | C23: Status | D23: Behördliche / Betreiberanforderungen separat nachweisen.
A24: Nachweise / Aktenverweise | B24: Projektbezogene Nachweise fehlen; kein Freigabenachweis. | C24: – | D24: Status ist Selbstauskunft; dieses Tool prüft keine Nachweisdokumente.
A26: 03 Wirtschaftlichkeit
A27: Planungskosten | B27: 3000 | C27: € | D27: Einheitlicher Preisstand und Brutto-/Nettobezug für alle Kosten.
A28: Anlagenkosten | B28: 15000 | C28: € | D28: Beschaffung; keine Montage doppelt erfassen.
A29: Montagekosten | B29: 5000 | C29: € | D29: Einbau inklusive erforderlicher Leitungen erfassen.
A30: Sonstige Investitionskosten | B30: 2000 | C30: € | D30: Zusatzleistungen ohne Doppelzählung.
A31: Fördermittel bei Investition | B31: 0 | C31: € | D31: Jahr 0; höchstens Gesamtinvestition. In Varianten begrenzt auf Bruttoinvestition.
A32: Wartungskosten erstes Jahr | B32: 450 | C32: €/a | D32: Wiederkehrende Kosten; Preisentwicklung separat.
A33: Spezifische Aufbereitungsenergie | B33: 1 | C33: kWh/m³ | D33: Bezug: verarbeitetes Rohwasser, auch bei später ungenutztem Wasser.
A34: Strompreis erstes Jahr | B34: 0.3 | C34: €/kWh | D34: Projektbezogener Tarif.
A35: Sonstige Betriebskosten erstes Jahr | B35: 120 | C35: €/a | D35: Labor, Verbrauchsmaterial, Betreiberaufwand etc.
A36: Vermiedener Trinkwasserpreis | B36: 2.5 | C36: €/m³ | D36: Nur mengenabhängig vermeidbarer Anteil; Grundgebühren ausschließen.
A37: Abwassergebühr | B37: 2.2 | C37: €/m³ | D37: Keine automatische Einsparung; Gebührenregelung projektspezifisch.
A38: Anerkannter Abwasser-Einsparanteil | B38: 0 | C38: % | D38: Standard 0 %. Positiver Wert erfordert dokumentierte Gebührenentlastung.
... A46: Abwassergebührensteigerung | B46: 0.02 | C46: %/a | D46: Nur auf bestätigten mengenabhängigen Einsparanteil angewandt.
A47: Beleg der Gebührenentlastung | B47: Keine bestätigte Gebührenentlastung; Ansatz 0 %. | C47: – | D47: Bei positiver Anerkennung voreingestellten Text durch konkreten Beleg ersetzen.
A48: Datenstatus | B48: Beispieldaten | C48: Status | D48: Beispieldaten sind keine Entscheidungsgrundlage für das reale Projekt.

Sheet Nutzungsprofile
A1: Nutzergruppen & Mengen
A2: Dashboard | B2: Eingaben | C2: Profile | D2: Kalender | E2: Methodik
A3: Tage sind Jahres-Nutzungstage je Profil; Verteilung auf aktive Kalendertage der Gruppe. Quellen fachlich separat freigeben.
A5: Quelle / Nutzung | B5: Kalendergruppe | C5: Nutzer | D5: Nutzungen je Tag | E5: Liter je Nutzung | F5: Tage pro Jahr | G5: Jahresmenge m³ | H5: Aktive Kalendertage | I5: Prüfung | J5: Hinweise / Quelle
A6: Duschen Sporthalle | B6: Halle | C6: 120 | D6: 0.6 | E6: 25 | F6: 280 | G6: =IFERROR(C6*D6*E6*F6/1000,0) -> 504 | H6: =IF(B6="Schulbetrieb",SUM(Kalender!$C$5:$C$370),IF(B6="Halle",SUM(Kalender!$D$5:$D$370),IF(B6="Individuell",SUM(Kalender!$E$5:$E$370),0))) -> 280 | I6: =IFERROR(IF(AND(LEN(TRIM(A6))>0,OR(B6="Schulbetrieb",B6="Halle",B6="Individuell"),COUNT(C6:F6)=4,C6>=0,C6<=1000000,D6>=0,D6<=100,E6>=0,E6<=1000,F6>=0,F6<=366,MOD(F6,1)=0,OR(G6=0,F6<=H6)),"OK","FEHLER"),"FEHLER") -> OK | J6: Fiktiver Rechenansatz; Messung / Planungsnachweis ergänzen.
A7: Handwaschbecken Schule | B7: Schulbetrieb | C7: 300 | D7: 3 | E7: 1 | F7: 190 | G7: =IFERROR(C7*D7*E7*F7/1000,0) -> 171 | H7: =IF(B7="Schulbetrieb",SUM(Kalender!$C$5:$C$370),IF(B7="Halle",SUM(Kalender!$D$5:$D$370),IF(B7="Individuell",SUM(Kalender!$E$5:$E$370),0))) -> 190 | I7: =IFERROR(IF(AND(LEN(TRIM(A7))>0,OR(B7="Schulbetrieb",B7="Halle",B7="Individuell"),COUNT(C7:F7)=4,C7>=0,C7<=1000000,D7>=0,D7<=100,E7>=0,E7<=1000,F7>=0,F7<=366,MOD(F7,1)=0,OR(G7=0,F7<=H7)),"OK","FEHLER"),"FEHLER") -> OK | J7: Fiktiver Rechenansatz; Messung / Planungsnachweis ergänzen.
A8: Handwaschbecken Halle | B8: Halle | C8: 120 | D8: 2 | E8: 1 | F8: 280 | G8: =IFERROR(C8*D8*E8*F8/1000,0) -> 67.2 | H8: =IF(B8="Schulbetrieb",SUM(Kalender!$C$5:$C$370),IF(B8="Halle",SUM(Kalender!$D$5:$D$370),IF(B8="Individuell",SUM(Kalender!$E$5:$E$370),0))) -> 280 | I8: =IFERROR(IF(AND(LEN(TRIM(A8))>0,OR(B8="Schulbetrieb",B8="Halle",B8="Individuell"),COUNT(C8:F8)=4,C8>=0,C8<=1000000,D8>=0,D8<=100,E8>=0,E8<=1000,F8>=0,F8<=366,MOD(F8,1)=0,OR(G8=0,F8<=H8)),"OK","FEHLER"),"FEHLER") -> OK | J8: Fiktiver Rechenansatz; Messung / Planungsnachweis ergänzen.
A9: Weitere zulässige Quelle 1 | B9: Individuell | C9: 0 | D9: 0 | E9: 0 | F9: 0 | G9: =IFERROR(C9*D9*E9*F9/1000,0) -> 0 | H9: =IF(B9="Schulbetrieb",SUM(Kalender!$C$5:$C$370),IF(B9="Halle",SUM(Kalender!$D$5:$D$370),IF(B9="Individuell",SUM(Kalender!$E$5:$E$370),0))) -> 0 | I9: =IFERROR(IF(AND(LEN(TRIM(A9))>0,OR(B9="Schulbetrieb",B9="Halle",B9="Individuell"),COUNT(C9:F9)=4,C9>=0,C9<=1000000,D9>=0,D9<=100,E9>=0,E9<=1000,F9>=0,F9<=366,MOD(F9,1)=0,OR(G9=0,F9<=H9)),"OK","FEHLER"),"FEHLER") -> OK | J9: Fiktiver Rechenansatz; Messung / Planungsnachweis ergänzen.
A10: Weitere zulässige Quelle 2 | B10: Individuell | C10: 0 | D10: 0 | E10: 0 | F10: 0 | G10: =IFERROR(C10*D10*E10*F10/1000,0) -> 0 | H10: =IF(B10="Schulbetrieb",SUM(Kalender!$C$5:$C$370),IF(B10="Halle",SUM(Kalender!$D$5:$D$370),IF(B10="Individuell",SUM(Kalender!$E$5:$E$370),0))) -> 0 | I10: =IFERROR(IF(AND(LEN(TRIM(A10))>0,OR(B10="Schulbetrieb",B10="Halle",B10="Individuell"),COUNT(C10:F10)=4,C10>=0,C10<=1000000,D10>=0,D10<=100,E10>=0,E10<=1000,F10>=0,F10<=366,MOD(F10,1)=0,OR(G10=0,F10<=H10)),"OK","FEHLER"),"FEHLER") -> OK | J10: Fiktiver Rechenansatz; Messung / Planungsnachweis ergänzen.
A11: Weitere zulässige Quelle 3 | B11: Individuell | C11: 0 | D11: 0 | E11: 0 | F11: 0 | G11: =IFERROR(C11*D11*E11*F11/1000,0) -> 0 | H11: =IF(B11="Schulbetrieb",SUM(Kalender!$C$5:$C$370),IF(B11="Halle",SUM(Kalender!$D$5:$D$370),IF(B11="Individuell",SUM(Kalender!$E$5:$E$370),0))) -> 0 | I11: =IFERROR(IF(AND(LEN(TRIM(A11))>0,OR(B11="Schulbetrieb",B11="Halle",B11="Individuell"),COUNT(C11:F11)=4,C11>=0,C11<=1000000,D11>=0,D11<=100,E11>=0,E11<=1000,F11>=0,F11<=366,MOD(F11,1)=0,OR(G11=0,F11<=H11)),"OK","FEHLER"),"FEHLER") -> OK | J11: Fiktiver Rechenansatz; Messung / Planungsnachweis ergänzen.
A13: Grauwasserquellen: Küchenabwasser und belastete Quellen nicht ungeprüft als zulässig ansetzen.
A16: Quelle / Nutzung | B16: Kalendergruppe | C16: Nutzer | D16: Nutzungen je Tag | E16: Liter je Nutzung | F16: Tage pro Jahr | G16: Jahresmenge m³ | H16: Aktive Kalendertage | I16: Prüfung | J16: Hinweise / Quelle
A17: WC Schule | B17: Schulbetrieb | C17: 300 | D17: 3 | E17: 4.5 | F17: 190 | G17: =IFERROR(C17*D17*E17*F17/1000,0) -> 769.5 | H17: =IF(B17="Schulbetrieb",SUM(Kalender!$C$5:$C$370),IF(B17="Halle",SUM(Kalender!$D$5:$D$370),IF(B17="Individuell",SUM(Kalender!$E$5:$E$370),0))) -> 190 | I17: =IFERROR(IF(AND(LEN(TRIM(A17))>0,OR(B17="Schulbetrieb",B17="Halle",B17="Individuell"),COUNT(C17:F17)=4,C17>=0,C17<=1000000,D17>=0,D17<=100,E17>=0,E17<=1000,F17>=0,F17<=366,MOD(F17,1)=0,OR(G17=0,F17<=H17)),"OK","FEHLER"),"FEHLER") -> OK | J17: Fiktiver Rechenansatz; Messung / Planungsnachweis ergänzen.
A18: WC Halle | B18: Halle | C18: 120 | D18: 1.5 | E18: 4.5 | F18: 280 | G18: =IFERROR(C18*D18*E18*F18/1000,0) -> 226.8 | H18: =IF(B18="Schulbetrieb",SUM(Kalender!$C$5:$C$370),IF(B18="Halle",SUM(Kalender!$D$5:$D$370),IF(B18="Individuell",SUM(Kalender!$E$5:$E$370),0))) -> 280 | I18: =IFERROR(IF(AND(LEN(TRIM(A18))>0,OR(B18="Schulbetrieb",B18="Halle",B18="Individuell"),COUNT(C18:F18)=4,C18>=0,C18<=1000000,D18>=0,D18<=100,E18>=0,E18<=1000,F18>=0,F18<=366,MOD(F18,1)=0,OR(G18=0,F18<=H18)),"OK","FEHLER"),"FEHLER") -> OK | J18: Fiktiver Rechenansatz; Messung / Planungsnachweis ergänzen.
A19: Urinale Halle | B19: Halle | C19: 80 | D19: 1 | E19: 1 | F19: 280 | G19: =IFERROR(C19*D19*E19*F19/1000,0) -> 22.4 | H19: =IF(B19="Schulbetrieb",SUM(Kalender!$C$5:$C$370),IF(B19="Halle",SUM(Kalender!$D$5:$D$370),IF(B19="Individuell",SUM(Kalender!$E$5:$E$370),0))) -> 280 | I19: =IFERROR(IF(AND(LEN(TRIM(A19))>0,OR(B19="Schulbetrieb",B19="Halle",B19="Individuell"),COUNT(C19:F19)=4,C19>=0,C19<=1000000,D19>=0,D19<=100,E19>=0,E19<=1000,F19>=0,F19<=366,MOD(F19,1)=0,OR(G19=0,F19<=H19)),"OK","FEHLER"),"FEHLER") -> OK | J19: Fiktiver Rechenansatz; Messung / Planungsnachweis ergänzen.
A20: Weitere zulässige Nutzung 1 | B20: Individuell | C20: 0 | D20: 0 | E20: 0 | F20: 0 | G20: =IFERROR(C20*D20*E20*F20/1000,0) -> 0 | H20: =IF(B20="Schulbetrieb",SUM(Kalender!$C$5:$C$370),IF(B20="Halle",SUM(Kalender!$D$5:$D$370),IF(B20="Individuell",SUM(Kalender!$E$5:$E$370),0))) -> 0 | I20: =IFERROR(IF(AND(LEN(TRIM(A20))>0,OR(B20="Schulbetrieb",B20="Halle",B20="Individuell"),COUNT(C20:F20)=4,C20>=0,C20<=1000000,D20>=0,D20<=100,E20>=0,E20<=1000,F20>=0,F20<=366,MOD(F20,1)=0,OR(G20=0,F20<=H20)),"OK","FEHLER"),"FEHLER") -> OK | J20: Fiktiver Rechenansatz; Messung / Planungsnachweis ergänzen.
A21: Weitere zulässige Nutzung 2 | B21: Individuell | C21: 0 | D21: 0 | E21: 0 | F21: 0 | G21: =IFERROR(C21*D21*E21*F21/1000,0) -> 0 | H21: =IF(B21="Schulbetrieb",SUM(Kalender!$C$5:$C$370),IF(B21="Halle",SUM(Kalender!$D$5:$D$370),IF(B21="Individuell",SUM(Kalender!$E$5:$E$370),0))) -> 0 | I21: =IFERROR(IF(AND(LEN(TRIM(A21))>0,OR(B21="Schulbetrieb",B21="Halle",B21="Individuell"),COUNT(C21:F21)=4,C21>=0,C21<=1000000,D21>=0,D21<=100,E21>=0,E21<=1000,F21>=0,F21<=366,MOD(F21,1)=0,OR(G21=0,F21<=H21)),"OK","FEHLER"),"FEHLER") -> OK | J21: Fiktiver Rechenansatz; Messung / Planungsnachweis ergänzen.
A22: Weitere zulässige Nutzung 3 | B22: Individuell | C22: 0 | D22: 0 | E22: 0 | F22: 0 | G22: =IFERROR(C22*D22*E22*F22/1000,0) -> 0 | H22: =IF(B22="Schulbetrieb",SUM(Kalender!$C$5:$C$370),IF(B22="Halle",SUM(Kalender!$D$5:$D$370),IF(B22="Individuell",SUM(Kalender!$E$5:$E$370),0))) -> 0 | I22: =IFERROR(IF(AND(LEN(TRIM(A22))>0,OR(B22="Schulbetrieb",B22="Halle",B22="Individuell"),COUNT(C22:F22)=4,C22>=0,C22<=1000000,D22>=0,D22<=100,E22>=0,E22<=1000,F22>=0,F22<=366,MOD(F22,1)=0,OR(G22=0,F22<=H22)),"OK","FEHLER"),"FEHLER") -> OK | J22: Fiktiver Rechenansatz; Messung / Planungsnachweis ergänzen.
A24: Tagesverteilung = Jahresmenge / aktive Gruppentage. Weniger Profiltage reduzieren die Tagesintensität gleichmäßig.
A25: Schule und Halle dürfen verschiedene Nutzerzahlen / Tage haben. Anzahl im Projektkopf ist nur informativ.
A26: Nutzungstage größer als aktive Gruppentage bei positivem Volumen sind ungültig. Kalender entsprechend ergänzen.

Sheet Kalender
A1: Tageskalender
A2: Dashboard | B2: Eingaben | C2: Profile | D2: Kalender | E2: Methodik
A3: 0 = inaktiv · 1 = aktiv. Fiktiv: 190 Schul-, 280 Hallentage; Ferien/Feiertage selbst abgleichen. Hallentage enthalten Wochenenden.
A4: Datum | B4: Wochentag | C4: Schulbetrieb 0/1 | D4: Halle 0/1 | E4: Individuell 0/1 | F4: Notiz / Datengrundlage | G4: Prüfung
A5: =IFERROR(IF(YEAR(DATE(Eingaben!$B$10,1,1)+0)=Eingaben!$B$10,DATE(Eingaben!$B$10,1,1)+0,""),"") -> 46023 | B5: =IF(A5="","",CHOOSE(WEEKDAY(A5,2),"Mo","Di","Mi","Do","Fr","Sa","So")) -> Do | C5: 1 | D5: 1 | E5: 0 | F5: Fiktives Kalenderprofil – zu ersetzen | G5: =IFERROR(IF(AND(COUNT(C5:E5)=3,OR(C5=0,C5=1),OR(D5=0,D5=1),OR(E5=0,E5=1),OR(A5<>"",SUM(C5:E5)=0)),"OK","FEHLER"),"FEHLER") -> OK
A6: =IFERROR(IF(YEAR(DATE(Eingaben!$B$10,1,1)+1)=Eingaben!$B$10,DATE(Eingaben!$B$10,1,1)+1,""),"") -> 46024 | B6: =IF(A6="","",CHOOSE(WEEKDAY(A6,2),"Mo","Di","Mi","Do","Fr","Sa","So")) -> Fr | C6: 1 | D6: 1 | E6: 0 | G6: =IFERROR(IF(AND(COUNT(C6:E6)=3,OR(C6=0,C6=1),OR(D6=0,D6=1),OR(E6=0,E6=1),OR(A6<>"",SUM(C6:E6)=0)),"OK","FEHLER"),"FEHLER") -> OK
A7: =IFERROR(IF(YEAR(DATE(Eingaben!$B$10,1,1)+2)=Eingaben!$B$10,DATE(Eingaben!$B$10,1,1)+2,""),"") -> 46025 | B7: =IF(A7="","",CHOOSE(WEEKDAY(A7,2),"Mo","Di","Mi","Do","Fr","Sa","So")) -> Sa | C7: 0 | D7: 1 | E7: 0 | G7: =IFERROR(IF(AND(COUNT(C7:E7)=3,OR(C7=0,C7=1),OR(D7=0,D7=1),OR(E7=0,E7=1),OR(A7<>"",SUM(C7:E7)=0)),"OK","FEHLER"),"FEHLER") -> OK
A8: =IFERROR(IF(YEAR(DATE(Eingaben!$B$10,1,1)+3)=Eingaben!$B$10,DATE(Eingaben!$B$10,1,1)+3,""),"") -> 46026 | B8: =IF(A8="","",CHOOSE(WEEKDAY(A8,2),"Mo","Di","Mi","Do","Fr","Sa","So")) -> So | C8: 0 | D8: 1 | E8: 0 | G8: =IFERROR(IF(AND(COUNT(C8:E8)=3,OR(C8=0,C8=1),OR(D8=0,D8=1),OR(E8=0,E8=1),OR(A8<>"",SUM(C8:E8)=0)),"OK","FEHLER"),"FEHLER") -> OK
A9: =IFERROR(IF(YEAR(DATE(Eingaben!$B$10,1,1)+4)=Eingaben!$B$10,DATE(Eingaben!$B$10,1,1)+4,""),"") -> 46027 | B9: =IF(A9="","",CHOOSE(WEEKDAY(A9,2),"Mo","Di","Mi","Do","Fr","Sa","So")) -> Mo | C9: 1 | D9: 1 | E9: 0 | G9: =IFERROR(IF(AND(COUNT(C9:E9)=3,OR(C9=0,C9=1),OR(D9=0,D9=1),OR(E9=0,E9=1),OR(A9<>"",SUM(C9:E9)=0)),"OK","FEHLER"),"FEHLER") -> OK
A10: =IFERROR(IF(YEAR(DATE(Eingaben!$B$10,1,1)+5)=Eingaben!$B$10,DATE(Eingaben!$B$10,1,1)+5,""),"") -> 46028 | B10: =IF(A10="","",CHOOSE(WEEKDAY(A10,2),"Mo","Di","Mi","Do","Fr","Sa","So")) -> Di | C10: 1 | D10: 1 | E10: 0 | G10: =IFERROR(IF(AND(COUNT(C10:E10)=3,OR(C10=0,C10=1),OR(D10=0,D10=1),OR(E10=0,E10=1),OR(A10<>"",SUM(C10:E10)=0)),"OK","FEHLER"),"FEHLER") -> OK
A11: =IFERROR(IF(YEAR(DATE(Eingaben!$B$10,1,1)+6)=Eingaben!$B$10,DATE(Eingaben!$B$10,1,1)+6,""),"") -> 46029 | B11: =IF(A11="","",CHOOSE(WEEKDAY(A11,2),"Mo","Di","Mi","Do","Fr","Sa","So")) -> Mi | C11: 1 | D11: 1 | E11: 0 | G11: =IFERROR(IF(AND(COUNT(C11:E11)=3,OR(C11=0,C11=1),OR(D11=0,D11=1),OR(E11=0,E11=1),OR(A11<>"",SUM(C11:E11)=0)),"OK","FEHLER"),"FEHLER") -> OK
A12: =IFERROR(IF(YEAR(DATE(Eingaben!$B$10,1,1)+7)=Eingaben!$B$10,DATE(Eingaben!$B$10,1,1)+7,""),"") -> 46030 | B12: =IF(A12="","",CHOOSE(WEEKDAY(A12,2),"Mo","Di","Mi","Do","Fr","Sa","So")) -> Do | C12: 1 | D12: 1 | E12: 0 | G12: =IFERROR(IF(AND(COUNT(C12:E12)=3,OR(C12=0,C12=1),OR(D12=0,D12=1),OR(E12=0,E12=1),OR(A12<>"",SUM(C12:E12)=0)),"OK","FEHLER"),"FEHLER") -> OK
A13: =IFERROR(IF(YEAR(DATE(Eingaben!$B$10,1,1)+8)=Eingaben!$B$10,DATE(Eingaben!$B$10,1,1)+8,""),"") -> 46031 | B13: =IF(A13="","",CHOOSE(WEEKDAY(A13,2),"Mo","Di","Mi","Do","Fr","Sa","So")) -> Fr | C13: 1 | D13: 1 | E13: 0 | G13: =IFERROR(IF(AND(COUNT(C13:E13)=3,OR(C13=0,C13=1),OR(D13=0,D13=1),OR(E13=0,E13=1),OR(A13<>"",SUM(C13:E13)=0)),"OK","FEHLER"),"FEHLER") -> OK
A14: =IFERROR(IF(YEAR(DATE(Eingaben!$B$10,1,1)+9)=Eingaben!$B$10,DATE(Eingaben!$B$10,1,1)+9,""),"") -> 46032 | B14: =IF(A14="","",CHOOSE(WEEKDAY(A14,2),"Mo","Di","Mi","Do","Fr","Sa","So")) -> Sa | C14: 0 | D14: 1 | E14: 0 | G14: =IFERROR(IF(AND(COUNT(C14:E14)=3,OR(C14=0,C14=1),OR(D14=0,D14=1),OR(E14=0,E14=1),OR(A14<>"",SUM(C14:E14)=0)),"OK","FEHLER"),"FEHLER") -> OK
A15: =IFERROR(IF(YEAR(DATE(Eingaben!$B$10,1,1)+10)=Eingaben!$B$10,DATE(Eingaben!$B$10,1,1)+10,""),"") -> 46033 | B15: =IF(A15="","",CHOOSE(WEEKDAY(A15,2),"Mo","Di","Mi","Do","Fr","Sa","So")) -> So | C15: 0 | D15: 1 | E15: 0 | G15: =IFERROR(IF(AND(COUNT(C15:E15)=3,OR(C15=0,C15=1),OR(D15=0,D15=1),OR(E15=0,E15=1),OR(A15<>"",SUM(C15:E15)=0)),"OK","FEHLER"),"FEHLER") -> OK
A16: =IFERROR(IF(YEAR(DATE(Eingaben!$B$10,1,1)+11)=Eingaben!$B$10,DATE(Eingaben!$B$10,1,1)+11,""),"") -> 46034 | B16: =IF(A16="","",CHOOSE(WEEKDAY(A16,2),"Mo","Di","Mi","Do","Fr","Sa","So")) -> Mo | C16: 1 | D16: 1 | E16: 0 | G16: =IFERROR(IF(AND(COUNT(C16:E16)=3,OR(C16=0,C16=1),OR(D16=0,D16=1),OR(E16=0,E16=1),OR(A16<>"",SUM(C16:E16)=0)),"OK","FEHLER"),"FEHLER") -> OK
A17: =IFERROR(IF(YEAR(DATE(Eingaben!$B$10,1,1)+12)=Eingaben!$B$10,DATE(Eingaben!$B$10,1,1)+12,""),"") -> 46035 | B17: =IF(A17="","",CHOOSE(WEEKDAY(A17,2),"Mo","Di","Mi","Do","Fr","Sa","So")) -> Di | C17: 1 | D17: 1 | E17: 0 | G17: =IFERROR(IF(AND(COUNT(C17:E17)=3,OR(C17=0,C17=1),OR(D17=0,D17=1),OR(E17=0,E17=1),OR(A17<>"",SUM(C17:E17)=0)),"OK","FEHLER"),"FEHLER") -> OK
A18: =IFERROR(IF(YEAR(DATE(Eingaben!$B$10,1,1)+13)=Eingaben!$B$10,DATE(Eingaben!$B$10,1,1)+13,""),"") -> 46036 | B18: =IF(A18="","",CHOOSE(WEEKDAY(A18,2),"Mo","Di","Mi","Do","Fr","Sa","So")) -> Mi | C18: 1 | D18: 1 | E18: 0 | G18: =IFERROR(IF(AND(COUNT(C18:E18)=3,OR(C18=0,C18=1),OR(D18=0,D18=1),OR(E18=0,E18=1),OR(A18<>"",SUM(C18:E18)=0)),"OK","FEHLER"),"FEHLER") -> OK
A19: =IFERROR(IF(YEAR(DATE(Eingaben!$B$10,1,1)+14)=Eingaben!$B$10,DATE(Eingaben!$B$10,1,1)+14,""),"") -> 46037 | B19: =IF(A19="","",CHOOSE(WEEKDAY(A19,2),"Mo","Di","Mi","Do","Fr","Sa","So")) -> Do | C19: 1 | D19: 1 | E19: 0 | G19: =IFERROR(IF(AND(COUNT(C19:E19)=3,OR(C19=0,C19=1),OR(D19=0,D19=1),OR(E19=0,E19=1),OR(A19<>"",SUM(C19:E19)=0)),"OK","FEHLER"),"FEHLER") -> OK
A20: =IFERROR(IF(YEAR(DATE(Eingaben!$B$10,1,1)+15)=Eingaben!$B$10,DATE(Eingaben!$B$10,1,1)+15,""),"") -> 46038 | B20: =IF(A20="","",CHOOSE(WEEKDAY(A20,2),"Mo","Di","Mi","Do","Fr","Sa","So")) -> Fr | C20: 1 | D20: 1 | E20: 0 | G20: =IFERROR(IF(AND(COUNT(C20:E20)=3,OR(C20=0,C20=1),OR(D20=0,D20=1),OR(E20=0,E20=1),OR(A20<>"",SUM(C20:E20)=0)),"OK","FEHLER"),"FEHLER") -> OK
A21: =IFERROR(IF(YEAR(DATE(Eingaben!$B$10,1,1)+16)=Eingaben!$B$10,DATE(Eingaben!$B$10,1,1)+16,""),"") -> 46039 | B21: =IF(A21="","",CHOOSE(WEEKDAY(A21,2),"Mo","Di","Mi","Do","Fr","Sa","So")) -> Sa | C21: 0 | D21: 1 | E21: 0 | G21: =IFERROR(IF(AND(COUNT(C21:E21)=3,OR(C21=0,C21=1),OR(D21=0,D21=1),OR(E21=0,E21=1),OR(A21<>"",SUM(C21:E21)=0)),"OK","FEHLER"),"FEHLER") -> OK
A22: =IFERROR(IF(YEAR(DATE(Eingaben!$B$10,1,1)+17)=Eingaben!$B$10,DATE(Eingaben!$B$10,1,1)+17,""),"") -> 46040 | B22: =IF(A22="","",CHOOSE(WEEKDAY(A22,2),"Mo","Di","Mi","Do","Fr","Sa","So")) -> So | C22: 0 | D22: 1 | E22: 0 | G22: =IFERROR(IF(AND(COUNT(C22:E22)=3,OR(C22=0,C22=1),OR(D22=0,D22=1),OR(E22=0,E22=1),OR(A22<>"",SUM(C22:E22)=0)),"OK","FEHLER"),"FEHLER") -> OK
A23: =IFERROR(IF(YEAR(DATE(Eingaben!$B$10,1,1)+18)=Eingaben!$B$10,DATE(Eingaben!$B$10,1,1)+18,""),"") -> 46041 | B23: =IF(A23="","",CHOOSE(WEEKDAY(A23,2),"Mo","Di","Mi","Do","Fr","Sa","So")) -> Mo | C23: 1 | D23: 1 | E23: 0 | G23: =IFERROR(IF(AND(COUNT(C23:E23)=3,OR(C23=0,C23=1),OR(D23=0,D23=1),OR(E23=0,E23=1),OR(A23<>"",SUM(C23:E23)=0)),"OK","FEHLER"),"FEHLER") -> OK
A24: =IFERROR(IF(YEAR(DATE(Eingaben!$B$10,1,1)+19)=Eingaben!$B$10,DATE(Eingaben!$B$10,1,1)+19,""),"") -> 46042 | B24: =IF(A24="","",CHOOSE(WEEKDAY(A24,2),"Mo","Di","Mi","Do","Fr","Sa","So")) -> Di | C24: 1 | D24: 1 | E24: 0 | G24: =IFERROR(IF(AND(COUNT(C24:E24)=3,OR(C24=0,C24=1),OR(D24=0,D24=1),OR(E24=0,E24=1),OR(A24<>"",SUM(C24:E24)=0)),"OK","FEHLER"),"FEHLER") -> OK
A25: =IFERROR(IF(YEAR(DATE(Eingaben!$B$10,1,1)+20)=Eingaben!$B$10,DATE(Eingaben!$B$10,1,1)+20,""),"") -> 46043 | B25: =IF(A25="","",CHOOSE(WEEKDAY(A25,2),"Mo","Di","Mi","Do","Fr","Sa","So")) -> Mi | C25: 1 | D25: 1 | E25: 0 | G25: =IFERROR(IF(AND(COUNT(C25:E25)=3,OR(C25=0,C25=1),OR(D25=0,D25=1),OR(E25=0,E25=1),OR(A25<>"",SUM(C25:E25)=0)),"OK","FEHLER"),"FEHLER") -> OK
A26: =IFERROR(IF(YEAR(DATE(Eingaben!$B$10,1,1)+21)=Eingaben!$B$10,DATE(Eingaben!$B$10,1,1)+21,""),"") -> 46044 | B26: =IF(A26="","",CHOOSE(WEEKDAY(A26,2),"Mo","Di","Mi","Do","Fr","Sa","So")) -> Do | C26: 1 | D26: 1 | E26: 0 | G26: =IFERROR(IF(AND(COUNT(C26:E26)=3,OR(C26=0,C26=1),OR(D26=0,D26=1),OR(E26=0,E26=1),OR(A26<>"",SUM(C26:E26)=0)),"OK","FEHLER"),"FEHLER") -> OK
A27: =IFERROR(IF(YEAR(DATE(Eingaben!$B$10,1,1)+22)=Eingaben!$B$10,DATE(Eingaben!$B$10,1,1)+22,""),"") -> 46045 | B27: =IF(A27="","",CHOOSE(WEEKDAY(A27,2),"Mo","Di","Mi","Do","Fr","Sa","So")) -> Fr | C27: 1 | D27: 1 | E27: 0 | G27: =IFERROR(IF(AND(COUNT(C27:E27)=3,OR(C27=0,C27=1),OR(D27=0,D27=1),OR(E27=0,E27=1),OR(A27<>"",SUM(C27:E27)=0)),"OK","FEHLER"),"FEHLER") -> OK
A28: =IFERROR(IF(YEAR(DATE(Eingaben!$B$10,1,1)+23)=Eingaben!$B$10,DATE(Eingaben!$B$10,1,1)+23,""),"") -> 46046 | B28: =IF(A28="","",CHOOSE(WEEKDAY(A28,2),"Mo","Di","Mi","Do","Fr","Sa","So")) -> Sa | C28: 0 | D28: 1 | E28: 0 | G28: =IFERROR(IF(AND(COUNT(C28:E28)=3,OR(C28=0,C28=1),OR(D28=0,D28=1),OR(E28=0,E28=1),OR(A28<>"",SUM(C28:E28)=0)),"OK","FEHLER"),"FEHLER") -> OK
A29: =IFERROR(IF(YEAR(DATE(Eingaben!$B$10,1,1)+24)=Eingaben!$B$10,DATE(Eingaben!$B$10,1,1)+24,""),"") -> 46047 | B29: =IF(A29="","",CHOOSE(WEEKDAY(A29,2),"Mo","Di","Mi","Do","Fr","Sa","So")) -> So | C29: 0 | D29: 1 | E29: 0 | G29: =IFERROR(IF(AND(COUNT(C29:E29)=3,OR(C29=0,C29=1),OR(D29=0,D29=1),OR(E29=0,E29=1),OR(A29<>"",SUM(C29:E29)=0)),"OK","FEHLER"),"FEHLER") -> OK
A30: =IFERROR(IF(YEAR(DATE(Eingaben!$B$10,1,1)+25)=Eingaben!$B$10,DATE(Eingaben!$B$10,1,1)+25,""),"") -> 46048 | B30: =IF(A30="","",CHOOSE(WEEKDAY(A30,2),"Mo","Di","Mi","Do","Fr","Sa","So")) -> Mo | C30: 1 | D30: 1 | E30: 0 | G30: =IFERROR(IF(AND(COUNT(C30:E30)=3,OR(C30=0,C30=1),OR(D30=0,D30=1),OR(E30=0,E30=1),OR(A30<>"",SUM(C30:E30)=0)),"OK","FEHLER"),"FEHLER") -> OK
A31: =IFERROR(IF(YEAR(DATE(Eingaben!$B$10,1,1)+26)=Eingaben!$B$10,DATE(Eingaben!$B$10,1,1)+26,""),"") -> 46049 | B31: =IF(A31="","",CHOOSE(WEEKDAY(A31,2),"Mo","Di","Mi","Do","Fr","Sa","So")) -> Di | C31: 1 | D31: 1 | E31: 0 | G31: =IFERROR(IF(AND(COUNT(C31:E31)=3,OR(C31=0,C31=1),OR(D31=0,D31=1),OR(E31=0,E31=1),OR(A31<>"",SUM(C31:E31)=0)),"OK","FEHLER"),"FEHLER") -> OK
A32: =IFERROR(IF(YEAR(DATE(Eingaben!$B$10,1,1)+27)=Eingaben!$B$10,DATE(Eingaben!$B$10,1,1)+27,""),"") -> 46050 | B32: =IF(A32="","",CHOOSE(WEEKDAY(A32,2),"Mo","Di","Mi","Do","Fr","Sa","So")) -> Mi | C32: 1 | D32: 1 | E32: 0 | G32: =IFERROR(IF(AND(COUNT(C32:E32)=3,OR(C32=0,C32=1),OR(D32=0,D32=1),OR(E32=0,E32=1),OR(A32<>"",SUM(C32:E32)=0)),"OK","FEHLER"),"FEHLER") -> OK
A33: =IFERROR(IF(YEAR(DATE(Eingaben!$B$10,1,1)+28)=Eingaben!$B$10,DATE(Eingaben!$B$10,1,1)+28,""),"") -> 46051 | B33: =IF(A33="","",CHOOSE(WEEKDAY(A33,2),"Mo","Di","Mi","Do","Fr","Sa","So")) -> Do | C33: 1 | D33: 1 | E33: 0 | G33: =IFERROR(IF(AND(COUNT(C33:E33)=3,OR(C33=0,C33=1),OR(D33=0,D33=1),OR(E33=0,E33=1),OR(A33<>"",SUM(C33:E33)=0)),"OK","FEHLER"),"FEHLER") -> OK
A34: =IFERROR(IF(YEAR(DATE(Eingaben!$B$10,1,1)+29)=Eingaben!$B$10,DATE(Eingaben!$B$10,1,1)+29,""),"") -> 46052 | B34: =IF(A34="","",CHOOSE(WEEKDAY(A34,2),"Mo","Di","Mi","Do","Fr","Sa","So")) -> Fr | C34: 1 | D34: 1 | E34: 0 | G34: =IFERROR(IF(AND(COUNT(C34:E34)=3,OR(C34=0,C34=1),OR(D34=0,D34=1),OR(E34=0,E34=1),OR(A34<>"",SUM(C34:E34)=0)),"OK","FEHLER"),"FEHLER") -> OK
A35: =IFERROR(IF(YEAR(DATE(Eingaben!$B$10,1,1)+30)=Eingaben!$B$10,DATE(Eingaben!$B$10,1,1)+30,""),"") -> 46053 | B35: =IF(A35="","",CHOOSE(WEEKDAY(A35,2),"Mo","Di","Mi","Do","Fr","Sa","So")) -> Sa | C35: 0 | D35: 1 | E35: 0 | G35: =IFERROR(IF(AND(COUNT(C35:E35)=3,OR(C35=0,C35=1),OR(D35=0,D35=1),OR(E35=0,E35=1),OR(A35<>"",SUM(C35:E35)=0)),"OK","FEHLER"),"FEHLER") -> OK
A36: =IFERROR(IF(YEAR(DATE(Eingaben!$B$10,1,1)+31)=Eingaben!$B$10,DATE(Eingaben!$B$10,1,1)+31,""),"") -> 46054 | B36: =IF(A36="","",CHOOSE(WEEKDAY(A36,2),"Mo","Di","Mi","Do","Fr","Sa","So")) -> So | C36: 0 | D36: 1 | E36: 0 | G36: =IFERROR(IF(AND(COUNT(C36:E36)=3,OR(C36=0,C36=1),OR(D36=0,D36=1),OR(E36=0,E36=1),OR(A36<>"",SUM(C36:E36)=0)),"OK","FEHLER"),"FEHLER") -> OK
A37: =IFERROR(IF(YEAR(DATE(Eingaben!$B$10,1,1)+32)=Eingaben!$B$10,DATE(Eingaben!$B$10,1,1)+32,""),"") -> 46055 | B37: =IF(A37="","",CHOOSE(WEEKDAY(A37,2),"Mo","Di","Mi","Do","Fr","Sa","So")) -> Mo | C37: 1 | D37: 1 | E37: 0 | G37: =IFERROR(IF(AND(COUNT(C37:E37)=3,OR(C37=0,C37=1),OR(D37=0,D37=1),OR(E37=0,E37=1),OR(A37<>"",SUM(C37:E37)=0)),"OK","FEHLER"),"FEHLER") -> OK
A38: =IFERROR(IF(YEAR(DATE(Eingaben!$B$10,1,1)+33)=Eingaben!$B$10,DATE(Eingaben!$B$10,1,1)+33,""),"") -> 46056 | B38: =IF(A38="","",CHOOSE(WEEKDAY(A38,2),"Mo","Di","Mi","Do","Fr","Sa","So")) -> Di | C38: 1 | D38: 1 | E38: 0 | G38: =IFERROR(IF(AND(COUNT(C38:E38)=3,OR(C38=0,C38=1),OR(D38=0,D38=1),OR(E38=0,E38=1),OR(A38<>"",SUM(C38:E38)=0)),"OK","FEHLER"),"FEHLER") -> OK
A39: =IFERROR(IF(YEAR(DATE(Eingaben!$B$10,1,1)+34)=Eingaben!$B$10,DATE(Eingaben!$B$10,1,1)+34,""),"") -> 46057 | B39: =IF(A39="","",CHOOSE(WEEKDAY(A39,2),"Mo","Di","Mi","Do","Fr","Sa","So")) -> Mi | C39: 1 | D39: 1 | E39: 0 | G39: =IFERROR(IF(AND(COUNT(C39:E39)=3,OR(C39=0,C39=1),OR(D39=0,D39=1),OR(E39=0,E39=1),OR(A39<>"",SUM(C39:E39)=0)),"OK","FEHLER"),"FEHLER") -> OK
A40: =IFERROR(IF(YEAR(DATE(Eingaben!$B$10,1,1)+35)=Eingaben!$B$10,DATE(Eingaben!$B$10,1,1)+35,""),"") -> 46058 | B40: =IF(A40="","",CHOOSE(WEEKDAY(A40,2),"Mo","Di","Mi","Do","Fr","Sa","So")) -> Do | C40: 1 | D40: 1 | E40: 0 | G40: =IFERROR(IF(AND(COUNT(C40:E40)=3,OR(C40=0,C40=1),OR(D40=0,D40=1),OR(E40=0,E40=1),OR(A40<>"",SUM(C40:E40)=0)),"OK","FEHLER"),"FEHLER") -> OK
...

Sheet Schwellenwerte
A1: Ampelmodell & Schwellen
A2: Dashboard | B2: Eingaben | C2: Profile | D2: Kalender | E2: Methodik
A3: Alle Grenzwerte sind vorläufige Modellannahmen, keine normativen oder empirisch validierten Eignungsgrenzen.
A4: Kriterium | B4: Schwelle | C4: Einheit | D4: Status / Interpretation | E4: Begründung
A5: Ökonomie Grün ab | B5: 0 | C5: NPV / Nettoinvestition | D5: Vorläufig · zu validieren | E5: Grün ab Kapitalwert ≥ 0 bei Basisschwelle 0 %.
A6: Ökonomie Gelb ab | B6: -0.2 | C6: NPV / Nettoinvestition | D6: Vorläufig · zu validieren | E6: Verlust bis 20 % des Kapitaleinsatzes als vorläufiger Prüfbereich.
A9: Ressourcen Grün ab | B9: 0.15 | C9: Anteil Baseline-Trinkwasser | D9: Vorläufig · zu validieren | E9: Vorläufig: 15 % der Baseline aus Betriebsbedarf + sonstigem Bedarf.
A10: Ressourcen Gelb ab | B10: 0.05 | C10: Anteil Baseline-Trinkwasser | D10: Vorläufig · zu validieren | E10: Vorläufig: 5 %; keine Literaturgrenze.
A13: Aggregation: schlechteste Kategorie entscheidet (konservatives Maximum). Keine kompensatorische gewichtete Summe.
A14: Grün / Gelb / Rot entsprechen günstiger / bedingter / ungünstiger Eignung innerhalb dieses Modells.
A15: Nachweise: Nicht erfüllt → Rot; Ungeklärt → mindestens Gelb + Prüfbedarf; alle Nachgewiesen → keine Begrenzung.
A16: Fehlende oder ungültige Pflichtwerte → Nicht bewertbar; kein Ersatz durch Nullwerte im Dashboard.
A17: Keine Wassereinsparung → Ressourcen Rot unabhängig von Schwellen. Kein Bedarf ist kein positiver Nutzen.
A18: Bei Nettoinvestition = 0: NPV ≥ 0 → ökonomisch Grün, NPV < 0 → Rot; Quotient ist nicht definiert.
A19: Technisch/hygienisch/rechtlich sind Nachweisstatus, keine vom Tool erteilte Freigabe. Selbstauskunft dokumentieren.
A20: Gewichtete Bewertung wurde verworfen: Kompensation verdeckt Konflikte, korrelierte KPIs würden doppelt zählen.
A21: Konservative Aggregation macht Zielkonflikte sichtbar; alternative Gewichte erst mit Beteiligten validieren.
A22: Wissenschaftliche Validierung: Schwellen begründen, Expertenreview und Sensitivität durchführen; Nutzertest separat.

Sheet Wasserbilanz
A1: Wasserbilanz · 366 Tageszeilen
A2: Dashboard | B2: Eingaben | C2: Profile | D2: Kalender | E2: Methodik
A3: m³ je Tag · Speicher aus Vortag zuerst nutzen, dann direkte Deckung; alte Reste spätestens am Tagesende verwerfen.
A4: Datum | B4: Schule | C4: Halle | D4: Rohgrauwasser | E4: Betriebsbedarf | F4: Verarbeitet | G4: Aufbereitet | H4: Altbestand nach Verlust | I4: Verbrauch Alt | J4: Direktverbrauch | K4: Endbestand frisch | L4: Wiederverwendung | M4: Nachspeisung | N4: Überschuss frisch | O4: Speicherverlust / Alt | P4: Bilanzrest | Q4: Tank Vortag
A5: =Kalender!A5 -> 46023 | B5: =Kalender!C5 -> 1 | C5: =Kalender!D5 -> 1 | D5: =IF(Prüfungen!$B$4=0,(IFERROR(SUMIF(Nutzungsprofile!$B$6:$B$11,"Schulbetrieb",Nutzungsprofile!$G$6:$G$11)*Kalender!C5/SUM(Kalender!$C$5:$C$370),0)+IFERROR(SUMIF(Nutzungsprofile!$B$6:$B$11,"Halle",Nutzungsprofile!$G$6:$G$11)*Kalender!D5/SUM(Kalender!$D$5:$D$370),0)+IFERROR(SUMIF(Nutzungsprofile!$B$6:$B$11,"Individuell",Nutzungsprofile!$G$6:$G$11)*Kalender!E5/SUM(Kalender!$E$5:$E$370),0)),0) -> 2.94 | E5: =IF(Prüfungen!$B$4=0,(IFERROR(SUMIF(Nutzungsprofile!$B$17:$B$22,"Schulbetrieb",Nutzungsprofile!$G$17:$G$22)*Kalender!C5/SUM(Kalender!$C$5:$C$370),0)+IFERROR(SUMIF(Nutzungsprofile!$B$17:$B$22,"Halle",Nutzungsprofile!$G$17:$G$22)*Kalender!D5/SUM(Kalender!$D$5:$D$370),0)+IFERROR(SUMIF(Nutzungsprofile!$B$17:$B$22,"Individuell",Nutzungsprofile!$G$17:$G$22)*Kalender!E5/SUM(Kalender!$E$5:$E$370),0)),0) -> 4.94 | F5: =IFERROR(MIN(D5,Eingaben!$B$17)*Eingaben!$B$16,0) -> 2.793 | G5: =IFERROR(F5*Eingaben!$B$15,0) -> 2.5137 | H5: =IFERROR(Q5*(1-Eingaben!$B$20),0) -> 0 | I5: =MIN(H5,E5) -> 0 | J5: =IFERROR(MIN(G5*Eingaben!$B$19,MAX(0,E5-I5)),0) -> 1.75959 | K5: =IFERROR(MIN(Eingaben!$B$18,MAX(0,G5-J5)),0) -> 0.75411 | L5: =I5+J5 -> 1.75959 | M5: =MAX(0,E5-L5) -> 3.18041 | N5: =MAX(0,G5-J5-K5) -> 0 | O5: =Q5-I5 -> 0 | P5: =G5+Q5-L5-N5-O5-K5 -> 0 | Q5: =0 -> 0
A6: =Kalender!A6 -> 46024 | B6: =Kalender!C6 -> 1 | C6: =Kalender!D6 -> 1 | D6: =IF(Prüfungen!$B$4=0,(IFERROR(SUMIF(Nutzungsprofile!$B$6:$B$11,"Schulbetrieb",Nutzungsprofile!$G$6:$G$11)*Kalender!C6/SUM(Kalender!$C$5:$C$370),0)+IFERROR(SUMIF(Nutzungsprofile!$B$6:$B$11,"Halle",Nutzungsprofile!$G$6:$G$11)*Kalender!D6/SUM(Kalender!$D$5:$D$370),0)+IFERROR(SUMIF(Nutzungsprofile!$B$6:$B$11,"Individuell",Nutzungsprofile!$G$6:$G$11)*Kalender!E6/SUM(Kalender!$E$5:$E$370),0)),0) -> 2.94 | E6: =IF(Prüfungen!$B$4=0,(IFERROR(SUMIF(Nutzungsprofile!$B$17:$B$22,"Schulbetrieb",Nutzungsprofile!$G$17:$G$22)*Kalender!C6/SUM(Kalender!$C$5:$C$370),0)+IFERROR(SUMIF(Nutzungsprofile!$B$17:$B$22,"Halle",Nutzungsprofile!$G$17:$G$22)*Kalender!D6/SUM(Kalender!$D$5:$D$370),0)+IFERROR(SUMIF(Nutzungsprofile!$B$17:$B$22,"Individuell",Nutzungsprofile!$G$17:$G$22)*Kalender!E6/SUM(Kalender!$E$5:$E$370),0)),0) -> 4.94 | F6: =IFERROR(MIN(D6,Eingaben!$B$17)*Eingaben!$B$16,0) -> 2.793 | G6: =IFERROR(F6*Eingaben!$B$15,0) -> 2.5137 | H6: =IFERROR(Q6*(1-Eingaben!$B$20),0) -> 0.7390278 | I6: =MIN(H6,E6) -> 0.7390278 | J6: =IFERROR(MIN(G6*Eingaben!$B$19,MAX(0,E6-I6)),0) -> 1.75959 | K6: =IFERROR(MIN(Eingaben!$B$18,MAX(0,G6-J6)),0) -> 0.75411 | L6: =I6+J6 -> 2.4986178 | M6: =MAX(0,E6-L6) -> 2.4413822 | N6: =MAX(0,G6-J6-K6) -> 0 | O6: =Q6-I6 -> 0.0150822 | P6: =G6+Q6-L6-N6-O6-K6 -> 0 | Q6: =IF(A6="",0,K5) -> 0.75411
A7: =Kalender!A7 -> 46025 | B7: =Kalender!C7 -> 0 | C7: =Kalender!D7 -> 1 | D7: =IF(Prüfungen!$B$4=0,(IFERROR(SUMIF(Nutzungsprofile!$B$6:$B$11,"Schulbetrieb",Nutzungsprofile!$G$6:$G$11)*Kalender!C7/SUM(Kalender!$C$5:$C$370),0)+IFERROR(SUMIF(Nutzungsprofile!$B$6:$B$11,"Halle",Nutzungsprofile!$G$6:$G$11)*Kalender!D7/SUM(Kalender!$D$5:$D$370),0)+IFERROR(SUMIF(Nutzungsprofile!$B$6:$B$11,"Individuell",Nutzungsprofile!$G$6:$G$11)*Kalender!E7/SUM(Kalender!$E$5:$E$370),0)),0) -> 2.04 | E7: =IF(Prüfungen!$B$4=0,(IFERROR(SUMIF(Nutzungsprofile!$B$17:$B$22,"Schulbetrieb",Nutzungsprofile!$G$17:$G$22)*Kalender!C7/SUM(Kalender!$C$5:$C$370),0)+IFERROR(SUMIF(Nutzungsprofile!$B$17:$B$22,"Halle",Nutzungsprofile!$G$17:$G$22)*Kalender!D7/SUM(Kalender!$D$5:$D$370),0)+IFERROR(SUMIF(Nutzungsprofile!$B$17:$B$22,"Individuell",Nutzungsprofile!$G$17:$G$22)*Kalender!E7/SUM(Kalender!$E$5:$E$370),0)),0) -> 0.89 | F7: =IFERROR(MIN(D7,Eingaben!$B$17)*Eingaben!$B$16,0) -> 1.938 | G7: =IFERROR(F7*Eingaben!$B$15,0) -> 1.7442 | H7: =IFERROR(Q7*(1-Eingaben!$B$20),0) -> 0.7390278 | I7: =MIN(H7,E7) -> 0.7390278 | J7: =IFERROR(MIN(G7*Eingaben!$B$19,MAX(0,E7-I7)),0) -> 0.1509722 | K7: =IFERROR(MIN(Eingaben!$B$18,MAX(0,G7-J7)),0) -> 1.5932278 | L7: =I7+J7 -> 0.89 | M7: =MAX(0,E7-L7) -> 0 | N7: =MAX(0,G7-J7-K7) -> 0 | O7: =Q7-I7 -> 0.0150822 | P7: =G7+Q7-L7-N7-O7-K7 -> 0 | Q7: =IF(A7="",0,K6) -> 0.75411
A8: =Kalender!A8 -> 46026 | B8: =Kalender!C8 -> 0 | C8: =Kalender!D8 -> 1 | D8: =IF(Prüfungen!$B$4=0,(IFERROR(SUMIF(Nutzungsprofile!$B$6:$B$11,"Schulbetrieb",Nutzungsprofile!$G$6:$G$11)*Kalender!C8/SUM(Kalender!$C$5:$C$370),0)+IFERROR(SUMIF(Nutzungsprofile!$B$6:$B$11,"Halle",Nutzungsprofile!$G$6:$G$11)*Kalender!D8/SUM(Kalender!$D$5:$D$370),0)+IFERROR(SUMIF(Nutzungsprofile!$B$6:$B$11,"Individuell",Nutzungsprofile!$G$6:$G$11)*Kalender!E8/SUM(Kalender!$E$5:$E$370),0)),0) -> 2.04 | E8: =IF(Prüfungen!$B$4=0,(IFERROR(SUMIF(Nutzungsprofile!$B$17:$B$22,"Schulbetrieb",Nutzungsprofile!$G$17:$G$22)*Kalender!C8/SUM(Kalender!$C$5:$C$370),0)+IFERROR(SUMIF(Nutzungsprofile!$B$17:$B$22,"Halle",Nutzungsprofile!$G$17:$G$22)*Kalender!D8/SUM(Kalender!$D$5:$D$370),0)+IFERROR(SUMIF(Nutzungsprofile!$B$17:$B$22,"Individuell",Nutzungsprofile!$G$17:$G$22)*Kalender!E8/SUM(Kalender!$E$5:$E$370),0)),0) -> 0.89 | F8: =IFERROR(MIN(D8,Eingaben!$B$17)*Eingaben!$B$16,0) -> 1.938 | G8: =IFERROR(F8*Eingaben!$B$15,0) -> 1.7442 | H8: =IFERROR(Q8*(1-Eingaben!$B$20),0) -> 1.5613632 | I8: =MIN(H8,E8) -> 0.89 | J8: =IFERROR(MIN(G8*Eingaben!$B$19,MAX(0,E8-I8)),0) -> 0 | K8: =IFERROR(MIN(Eingaben!$B$18,MAX(0,G8-J8)),0) -> 1.7442 | L8: =I8+J8 -> 0.89 | M8: =MAX(0,E8-L8) -> 0 | N8: =MAX(0,G8-J8-K8) -> 0 | O8: =Q8-I8 -> 0.7032278 | P8: =G8+Q8-L8-N8-O8-K8 -> 0 | Q8: =IF(A8="",0,K7) -> 1.5932278
A9: =Kalender!A9 -> 46027 | B9: =Kalender!C9 -> 1 | C9: =Kalender!D9 -> 1 | D9: =IF(Prüfungen!$B$4=0,(IFERROR(SUMIF(Nutzungsprofile!$B$6:$B$11,"Schulbetrieb",Nutzungsprofile!$G$6:$G$11)*Kalender!C9/SUM(Kalender!$C$5:$C$370),0)+IFERROR(SUMIF(Nutzungsprofile!$B$6:$B$11,"Halle",Nutzungsprofile!$G$6:$G$11)*Kalender!D9/SUM(Kalender!$D$5:$D$370),0)+IFERROR(SUMIF(Nutzungsprofile!$B$6:$B$11,"Individuell",Nutzungsprofile!$G$6:$G$11)*Kalender!E9/SUM(Kalender!$E$5:$E$370),0)),0) -> 2.94 | E9: =IF(Prüfungen!$B$4=0,(IFERROR(SUMIF(Nutzungsprofile!$B$17:$B$22,"Schulbetrieb",Nutzungsprofile!$G$17:$G$22)*Kalender!C9/SUM(Kalender!$C$5:$C$370),0)+IFERROR(SUMIF(Nutzungsprofile!$B$17:$B$22,"Halle",Nutzungsprofile!$G$17:$G$22)*Kalender!D9/SUM(Kalender!$D$5:$D$370),0)+IFERROR(SUMIF(Nutzungsprofile!$B$17:$B$22,"Individuell",Nutzungsprofile!$G$17:$G$22)*Kalender!E9/SUM(Kalender!$E$5:$E$370),0)),0) -> 4.94 | F9: =IFERROR(MIN(D9,Eingaben!$B$17)*Eingaben!$B$16,0) -> 2.793 | G9: =IFERROR(F9*Eingaben!$B$15,0) -> 2.5137 | H9: =IFERROR(Q9*(1-Eingaben!$B$20),0) -> 1.709316 | I9: =MIN(H9,E9) -> 1.709316 | J9: =IFERROR(MIN(G9*Eingaben!$B$19,MAX(0,E9-I9)),0) -> 1.75959 | K9: =IFERROR(MIN(Eingaben!$B$18,MAX(0,G9-J9)),0) -> 0.75411 | L9: =I9+J9 -> 3.468906 | M9: =MAX(0,E9-L9) -> 1.471094 | N9: =MAX(0,G9-J9-K9) -> 0 | O9: =Q9-I9 -> 0.034884 | P9: =G9+Q9-L9-N9-O9-K9 -> 0 | Q9: =IF(A9="",0,K8) -> 1.7442
A10: =Kalender!A10 -> 46028 | B10: =Kalender!C10 -> 1 | C10: =Kalender!D10 -> 1 | D10: =IF(Prüfungen!$B$4=0,(IFERROR(SUMIF(Nutzungsprofile!$B$6:$B$11,"Schulbetrieb",Nutzungsprofile!$G$6:$G$11)*Kalender!C10/SUM(Kalender!$C$5:$C$370),0)+IFERROR(SUMIF(Nutzungsprofile!$B$6:$B$11,"Halle",Nutzungsprofile!$G$6:$G$11)*Kalender!D10/SUM(Kalender!$D$5:$D$370),0)+IFERROR(SUMIF(Nutzungsprofile!$B$6:$B$11,"Individuell",Nutzungsprofile!$G$6:$G$11)*Kalender!E10/SUM(Kalender!$E$5:$E$370),0)),0) -> 2.94 | E10: =IF(Prüfungen!$B$4=0,(IFERROR(SUMIF(Nutzungsprofile!$B$17:$B$22,"Schulbetrieb",Nutzungsprofile!$G$17:$G$22)*Kalender!C10/SUM(Kalender!$C$5:$C$370),0)+IFERROR(SUMIF(Nutzungsprofile!$B$17:$B$22,"Halle",Nutzungsprofile!$G$17:$G$22)*Kalender!D10/SUM(Kalender!$D$5:$D$370),0)+IFERROR(SUMIF(Nutzungsprofile!$B$17:$B$22,"Individuell",Nutzungsprofile!$G$17:$G$22)*Kalender!E10/SUM(Kalender!$E$5:$E$370),0)),0) -> 4.94 | F10: =IFERROR(MIN(D10,Eingaben!$B$17)*Eingaben!$B$16,0) -> 2.793 | G10: =IFERROR(F10*Eingaben!$B$15,0) -> 2.5137 | H10: =IFERROR(Q10*(1-Eingaben!$B$20),0) -> 0.7390278 | I10: =MIN(H10,E10) -> 0.7390278 | J10: =IFERROR(MIN(G10*Eingaben!$B$19,MAX(0,E10-I10)),0) -> 1.75959 | K10: =IFERROR(MIN(Eingaben!$B$18,MAX(0,G10-J10)),0) -> 0.75411 | L10: =I10+J10 -> 2.4986178 | M10: =MAX(0,E10-L10) -> 2.4413822 | N10: =MAX(0,G10-J10-K10) -> 0 | O10: =Q10-I10 -> 0.0150822 | P10: =G10+Q10-L10-N10-O10-K10 -> 0 | Q10: =IF(A10="",0,K9) -> 0.75411
A11: =Kalender!A11 -> 46029 | B11: =Kalender!C11 -> 1 | C11: =Kalender!D11 -> 1 | D11: =IF(Prüfungen!$B$4=0,(IFERROR(SUMIF(Nutzungsprofile!$B$6:$B$11,"Schulbetrieb",Nutzungsprofile!$G$6:$G$11)*Kalender!C11/SUM(Kalender!$C$5:$C$370),0)+IFERROR(SUMIF(Nutzungsprofile!$B$6:$B$11,"Halle",Nutzungsprofile!$G$6:$G$11)*Kalender!D11/SUM(Kalender!$D$5:$D$370),0)+IFERROR(SUMIF(Nutzungsprofile!$B$6:$B$11,"Individuell",Nutzungsprofile!$G$6:$G$11)*Kalender!E11/SUM(Kalender!$E$5:$E$370),0)),0) -> 2.94 | E11: =IF(Prüfungen!$B$4=0,(IFERROR(SUMIF(Nutzungsprofile!$B$17:$B$22,"Schulbetrieb",Nutzungsprofile!$G$17:$G$22)*Kalender!C11/SUM(Kalender!$C$5:$C$370),0)+IFERROR(SUMIF(Nutzungsprofile!$B$17:$B$22,"Halle",Nutzungsprofile!$G$17:$G$22)*Kalender!D11/SUM(Kalender!$D$5:$D$370),0)+IFERROR(SUMIF(Nutzungsprofile!$B$17:$B$22,"Individuell",Nutzungsprofile!$G$17:$G$22)*Kalender!E11/SUM(Kalender!$E$5:$E$370),0)),0) -> 4.94 | F11: =IFERROR(MIN(D11,Eingaben!$B$17)*Eingaben!$B$16,0) -> 2.793 | G11: =IFERROR(F11*Eingaben!$B$15,0) -> 2.5137 | H11: =IFERROR(Q11*(1-Eingaben!$B$20),0) -> 0.7390278 | I11: =MIN(H11,E11) -> 0.7390278 | J11: =IFERROR(MIN(G11*Eingaben!$B$19,MAX(0,E11-I11)),0) -> 1.75959 | K11: =IFERROR(MIN(Eingaben!$B$18,MAX(0,G11-J11)),0) -> 0.75411 | L11: =I11+J11 -> 2.4986178 | M11: =MAX(0,E11-L11) -> 2.4413822 | N11: =MAX(0,G11-J11-K11) -> 0 | O11: =Q11-I11 -> 0.0150822 | P11: =G11+Q11-L11-N11-O11-K11 -> 0 | Q11: =IF(A11="",0,K10) -> 0.75411
A12: =Kalender!A12 -> 46030 | B12: =Kalender!C12 -> 1 | C12: =Kalender!D12 -> 1 | D12: =IF(Prüfungen!$B$4=0,(IFERROR(SUMIF(Nutzungsprofile!$B$6:$B$11,"Schulbetrieb",Nutzungsprofile!$G$6:$G$11)*Kalender!C12/SUM(Kalender!$C$5:$C$370),0)+IFERROR(SUMIF(Nutzungsprofile!$B$6:$B$11,"Halle",Nutzungsprofile!$G$6:$G$11)*Kalender!D12/SUM(Kalender!$D$5:$D$370),0)+IFERROR(SUMIF(Nutzungsprofile!$B$6:$B$11,"Individuell",Nutzungsprofile!$G$6:$G$11)*Kalender!E12/SUM(Kalender!$E$5:$E$370),0)),0) -> 2.94 | E12: =IF(Prüfungen!$B$4=0,(IFERROR(SUMIF(Nutzungsprofile!$B$17:$B$22,"Schulbetrieb",Nutzungsprofile!$G$17:$G$22)*Kalender!C12/SUM(Kalender!$C$5:$C$370),0)+IFERROR(SUMIF(Nutzungsprofile!$B$17:$B$22,"Halle",Nutzungsprofile!$G$17:$G$22)*Kalender!D12/SUM(Kalender!$D$5:$D$370),0)+IFERROR(SUMIF(Nutzungsprofile!$B$17:$B$22,"Individuell",Nutzungsprofile!$G$17:$G$22)*Kalender!E12/SUM(Kalender!$E$5:$E$370),0)),0) -> 4.94 | F12: =IFERROR(MIN(D12,Eingaben!$B$17)*Eingaben!$B$16,0) -> 2.793 | G12: =IFERROR(F12*Eingaben!$B$15,0) -> 2.5137 | H12: =IFERROR(Q12*(1-Eingaben!$B$20),0) -> 0.7390278 | I12: =MIN(H12,E12) -> 0.7390278 | J12: =IFERROR(MIN(G12*Eingaben!$B$19,MAX(0,E12-I12)),0) -> 1.75959 | K12: =IFERROR(MIN(Eingaben!$B$18,MAX(0,G12-J12)),0) -> 0.75411 | L12: =I12+J12 -> 2.4986178 | M12: =MAX(0,E12-L12) -> 2.4413822 | N12: =MAX(0,G12-J12-K12) -> 0 | O12: =Q12-I12 -> 0.0150822 | P12: =G12+Q12-L12-N12-O12-K12 -> 0 | Q12: =IF(A12="",0,K11) -> 0.75411
A13: =Kalender!A13 -> 46031 | B13: =Kalender!C13 -> 1 | C13: =Kalender!D13 -> 1 | D13: =IF(Prüfungen!$B$4=0,(IFERROR(SUMIF(Nutzungsprofile!$B$6:$B$11,"Schulbetrieb",Nutzungsprofile!$G$6:$G$11)*Kalender!C13/SUM(Kalender!$C$5:$C$370),0)+IFERROR(SUMIF(Nutzungsprofile!$B$6:$B$11,"Halle",Nutzungsprofile!$G$6:$G$11)*Kalender!D13/SUM(Kalender!$D$5:$D$370),0)+IFERROR(SUMIF(Nutzungsprofile!$B$6:$B$11,"Individuell",Nutzungsprofile!$G$6:$G$11)*Kalender!E13/SUM(Kalender!$E$5:$E$370),0)),0) -> 2.94 | E13: =IF(Prüfungen!$B$4=0,(IFERROR(SUMIF(Nutzungsprofile!$B$17:$B$22,"Schulbetrieb",Nutzungsprofile!$G$17:$G$22)*Kalender!C13/SUM(Kalender!$C$5:$C$370),0)+IFERROR(SUMIF(Nutzungsprofile!$B$17:$B$22,"Halle",Nutzungsprofile!$G$17:$G$22)*Kalender!D13/SUM(Kalender!$D$5:$D$370),0)+IFERROR(SUMIF(Nutzungsprofile!$B$17:$B$22,"Individuell",Nutzungsprofile!$G$17:$G$22)*Kalender!E13/SUM(Kalender!$E$5:$E$370),0)),0) -> 4.94 | F13: =IFERROR(MIN(D13,Eingaben!$B$17)*Eingaben!$B$16,0) -> 2.793 | G13: =IFERROR(F13*Eingaben!$B$15,0) -> 2.5137 | H13: =IFERROR(Q13*(1-Eingaben!$B$20),0) -> 0.7390278 | I13: =MIN(H13,E13) -> 0.7390278 | J13: =IFERROR(MIN(G13*Eingaben!$B$19,MAX(0,E13-I13)),0) -> 1.75959 | K13: =IFERROR(MIN(Eingaben!$B$18,MAX(0,G13-J13)),0) -> 0.75411 | L13: =I13+J13 -> 2.4986178 | M13: =MAX(0,E13-L13) -> 2.4413822 | N13: =MAX(0,G13-J13-K13) -> 0 | O13: =Q13-I13 -> 0.0150822 | P13: =G13+Q13-L13-N13-O13-K13 -> 0 | Q13: =IF(A13="",0,K12) -> 0.75411
A14: =Kalender!A14 -> 46032 | B14: =Kalender!C14 -> 0 | C14: =Kalender!D14 -> 1 | D14: =IF(Prüfungen!$B$4=0,(IFERROR(SUMIF(Nutzungsprofile!$B$6:$B$11,"Schulbetrieb",Nutzungsprofile!$G$6:$G$11)*Kalender!C14/SUM(Kalender!$C$5:$C$370),0)+IFERROR(SUMIF(Nutzungsprofile!$B$6:$B$11,"Halle",Nutzungsprofile!$G$6:$G$11)*Kalender!D14/SUM(Kalender!$D$5:$D$370),0)+IFERROR(SUMIF(Nutzungsprofile!$B$6:$B$11,"Individuell",Nutzungsprofile!$G$6:$G$11)*Kalender!E14/SUM(Kalender!$E$5:$E$370),0)),0) -> 2.04 | E14: =IF(Prüfungen!$B$4=0,(IFERROR(SUMIF(Nutzungsprofile!$B$17:$B$22,"Schulbetrieb",Nutzungsprofile!$G$17:$G$22)*Kalender!C14/SUM(Kalender!$C$5:$C$370),0)+IFERROR(SUMIF(Nutzungsprofile!$B$17:$B$22,"Halle",Nutzungsprofile!$G$17:$G$22)*Kalender!D14/SUM(Kalender!$D$5:$D$370),0)+IFERROR(SUMIF(Nutzungsprofile!$B$17:$B$22,"Individuell",Nutzungsprofile!$G$17:$G$22)*Kalender!E14/SUM(Kalender!$E$5:$E$370),0)),0) -> 0.89 | F14: =IFERROR(MIN(D14,Eingaben!$B$17)*Eingaben!$B$16,0) -> 1.938 | G14: =IFERROR(F14*Eingaben!$B$15,0) -> 1.7442 | H14: =IFERROR(Q14*(1-Eingaben!$B$20),0) -> 0.7390278 | I14: =MIN(H14,E14) -> 0.7390278 | J14: =IFERROR(MIN(G14*Eingaben!$B$19,MAX(0,E14-I14)),0) -> 0.1509722 | K14: =IFERROR(MIN(Eingaben!$B$18,MAX(0,G14-J14)),0) -> 1.5932278 | L14: =I14+J14 -> 0.89 | M14: =MAX(0,E14-L14) -> 0 | N14: =MAX(0,G14-J14-K14) -> 0 | O14: =Q14-I14 -> 0.0150822 | P14: =G14+Q14-L14-N14-O14-K14 -> 0 | Q14: =IF(A14="",0,K13) -> 0.75411
A15: =Kalender!A15 -> 46033 | B15: =Kalender!C15 -> 0 | C15: =Kalender!D15 -> 1 | D15: =IF(Prüfungen!$B$4=0,(IFERROR(SUMIF(Nutzungsprofile!$B$6:$B$11,"Schulbetrieb",Nutzungsprofile!$G$6:$G$11)*Kalender!C15/SUM(Kalender!$C$5:$C$370),0)+IFERROR(SUMIF(Nutzungsprofile!$B$6:$B$11,"Halle",Nutzungsprofile!$G$6:$G$11)*Kalender!D15/SUM(Kalender!$D$5:$D$370),0)+IFERROR(SUMIF(Nutzungsprofile!$B$6:$B$11,"Individuell",Nutzungsprofile!$G$6:$G$11)*Kalender!E15/SUM(Kalender!$E$5:$E$370),0)),0) -> 2.04 | E15: =IF(Prüfungen!$B$4=0,(IFERROR(SUMIF(Nutzungsprofile!$B$17:$B$22,"Schulbetrieb",Nutzungsprofile!$G$17:$G$22)*Kalender!C15/SUM(Kalender!$C$5:$C$370),0)+IFERROR(SUMIF(Nutzungsprofile!$B$17:$B$22,"Halle",Nutzungsprofile!$G$17:$G$22)*Kalender!D15/SUM(Kalender!$D$5:$D$370),0)+IFERROR(SUMIF(Nutzungsprofile!$B$17:$B$22,"Individuell",Nutzungsprofile!$G$17:$G$22)*Kalender!E15/SUM(Kalender!$E$5:$E$370),0)),0) -> 0.89 | F15: =IFERROR(MIN(D15,Eingaben!$B$17)*Eingaben!$B$16,0) -> 1.938 | G15: =IFERROR(F15*Eingaben!$B$15,0) -> 1.7442 | H15: =IFERROR(Q15*(1-Eingaben!$B$20),0) -> 1.5613632 | I15: =MIN(H15,E15) -> 0.89 | J15: =IFERROR(MIN(G15*Eingaben!$B$19,MAX(0,E15-I15)),0) -> 0 | K15: =IFERROR(MIN(Eingaben!$B$18,MAX(0,G15-J15)),0) -> 1.7442 | L15: =I15+J15 -> 0.89 | M15: =MAX(0,E15-L15) -> 0 | N15: =MAX(0,G15-J15-K15) -> 0 | O15: =Q15-I15 -> 0.7032278 | P15: =G15+Q15-L15-N15-O15-K15 -> 0 | Q15: =IF(A15="",0,K14) -> 1.5932278
A16: =Kalender!A16 -> 46034 | B16: =Kalender!C16 -> 1 | C16: =Kalender!D16 -> 1 | D16: =IF(Prüfungen!$B$4=0,(IFERROR(SUMIF(Nutzungsprofile!$B$6:$B$11,"Schulbetrieb",Nutzungsprofile!$G$6:$G$11)*Kalender!C16/SUM(Kalender!$C$5:$C$370),0)+IFERROR(SUMIF(Nutzungsprofile!$B$6:$B$11,"Halle",Nutzungsprofile!$G$6:$G$11)*Kalender!D16/SUM(Kalender!$D$5:$D$370),0)+IFERROR(SUMIF(Nutzungsprofile!$B$6:$B$11,"Individuell",Nutzungsprofile!$G$6:$G$11)*Kalender!E16/SUM(Kalender!$E$5:$E$370),0)),0) -> 2.94 | E16: =IF(Prüfungen!$B$4=0,(IFERROR(SUMIF(Nutzungsprofile!$B$17:$B$22,"Schulbetrieb",Nutzungsprofile!$G$17:$G$22)*Kalender!C16/SUM(Kalender!$C$5:$C$370),0)+IFERROR(SUMIF(Nutzungsprofile!$B$17:$B$22,"Halle",Nutzungsprofile!$G$17:$G$22)*Kalender!D16/SUM(Kalender!$D$5:$D$370),0)+IFERROR(SUMIF(Nutzungsprofile!$B$17:$B$22,"Individuell",Nutzungsprofile!$G$17:$G$22)*Kalender!E16/SUM(Kalender!$E$5:$E$370),0)),0) -> 4.94 | F16: =IFERROR(MIN(D16,Eingaben!$B$17)*Eingaben!$B$16,0) -> 2.793 | G16: =IFERROR(F16*Eingaben!$B$15,0) -> 2.5137 | H16: =IFERROR(Q16*(1-Eingaben!$B$20),0) -> 1.709316 | I16: =MIN(H16,E16) -> 1.709316 | J16: =IFERROR(MIN(G16*Eingaben!$B$19,MAX(0,E16-I16)),0) -> 1.75959 | K16: =IFERROR(MIN(Eingaben!$B$18,MAX(0,G16-J16)),0) -> 0.75411 | L16: =I16+J16 -> 3.468906 | M16: =MAX(0,E16-L16) -> 1.471094 | N16: =MAX(0,G16-J16-K16) -> 0 | O16: =Q16-I16 -> 0.034884 | P16: =G16+Q16-L16-N16-O16-K16 -> 0 | Q16: =IF(A16="",0,K15) -> 1.7442
A17: =Kalender!A17 -> 46035 | B17: =Kalender!C17 -> 1 | C17: =Kalender!D17 -> 1 | D17: =IF(Prüfungen!$B$4=0,(IFERROR(SUMIF(Nutzungsprofile!$B$6:$B$11,"Schulbetrieb",Nutzungsprofile!$G$6:$G$11)*Kalender!C17/SUM(Kalender!$C$5:$C$370),0)+IFERROR(SUMIF(Nutzungsprofile!$B$6:$B$11,"Halle",Nutzungsprofile!$G$6:$G$11)*Kalender!D17/SUM(Kalender!$D$5:$D$370),0)+IFERROR(SUMIF(Nutzungsprofile!$B$6:$B$11,"Individuell",Nutzungsprofile!$G$6:$G$11)*Kalender!E17/SUM(Kalender!$E$5:$E$370),0)),0) -> 2.94 | E17: =IF(Prüfungen!$B$4=0,(IFERROR(SUMIF(Nutzungsprofile!$B$17:$B$22,"Schulbetrieb",Nutzungsprofile!$G$17:$G$22)*Kalender!C17/SUM(Kalender!$C$5:$C$370),0)+IFERROR(SUMIF(Nutzungsprofile!$B$17:$B$22,"Halle",Nutzungsprofile!$G$17:$G$22)*Kalender!D17/SUM(Kalender!$D$5:$D$370),0)+IFERROR(SUMIF(Nutzungsprofile!$B$17:$B$22,"Individuell",Nutzungsprofile!$G$17:$G$22)*Kalender!E17/SUM(Kalender!$E$5:$E$370),0)),0) -> 4.94 | F17: =IFERROR(MIN(D17,Eingaben!$B$17)*Eingaben!$B$16,0) -> 2.793 | G17: =IFERROR(F17*Eingaben!$B$15,0) -> 2.5137 | H17: =IFERROR(Q17*(1-Eingaben!$B$20),0) -> 0.7390278 | I17: =MIN(H17,E17) -> 0.7390278 | J17: =IFERROR(MIN(G17*Eingaben!$B$19,MAX(0,E17-I17)),0) -> 1.75959 | K17: =IFERROR(MIN(Eingaben!$B$18,MAX(0,G17-J17)),0) -> 0.75411 | L17: =I17+J17 -> 2.4986178 | M17: =MAX(0,E17-L17) -> 2.4413822 | N17: =MAX(0,G17-J17-K17) -> 0 | O17: =Q17-I17 -> 0.0150822 | P17: =G17+Q17-L17-N17-O17-K17 -> 0 | Q17: =IF(A17="",0,K16) -> 0.75411
... A370: =Kalender!A370 | B370: =Kalender!C370 -> 0 | C370: =Kalender!D370 -> 0 | D370: =IF(Prüfungen!$B$4=0,(IFERROR(SUMIF(Nutzungsprofile!$B$6:$B$11,"Schulbetrieb",Nutzungsprofile!$G$6:$G$11)*Kalender!C370/SUM(Kalender!$C$5:$C$370),0)+IFERROR(SUMIF(Nutzungsprofile!$B$6:$B$11,"Halle",Nutzungsprofile!$G$6:$G$11)*Kalender!D370/SUM(Kalender!$D$5:$D$370),0)+IFERROR(SUMIF(Nutzungsprofile!$B$6:$B$11,"Individuell",Nutzungsprofile!$G$6:$G$11)*Kalender!E370/SUM(Kalender!$E$5:$E$370),0)),0) -> 0 | E370: =IF(Prüfungen!$B$4=0,(IFERROR(SUMIF(Nutzungsprofile!$B$17:$B$22,"Schulbetrieb",Nutzungsprofile!$G$17:$G$22)*Kalender!C370/SUM(Kalender!$C$5:$C$370),0)+IFERROR(SUMIF(Nutzungsprofile!$B$17:$B$22,"Halle",Nutzungsprofile!$G$17:$G$22)*Kalender!D370/SUM(Kalender!$D$5:$D$370),0)+IFERROR(SUMIF(Nutzungsprofile!$B$17:$B$22,"Individuell",Nutzungsprofile!$G$17:$G$22)*Kalender!E370/SUM(Kalender!$E$5:$E$370),0)),0) -> 0 | F370: =IFERROR(MIN(D370,Eingaben!$B$17)*Eingaben!$B$16,0) -> 0 | G370: =IFERROR(F370*Eingaben!$B$15,0) -> 0 | H370: =IFERROR(Q370*(1-Eingaben!$B$20),0) -> 0 | I370: =MIN(H370,E370) -> 0 | J370: =IFERROR(MIN(G370*Eingaben!$B$19,MAX(0,E370-I370)),0) -> 0 | K370: =IFERROR(MIN(Eingaben!$B$18,MAX(0,G370-J370)),0) -> 0 | L370: =I370+J370 -> 0 | M370: =MAX(0,E370-L370) -> 0 | N370: =MAX(0,G370-J370-K370) -> 0 | O370: =Q370-I370 -> 0 | P370: =G370+Q370-L370-N370-O370-K370 -> 0 | Q370: =IF(A370="",0,K369) -> 0

Sheet Zahlungen
A1: Zahlungsreihe & Kapitalwert
A2: Dashboard | B2: Eingaben | C2: Profile | D2: Kalender | E2: Methodik
A3: Nominale Zahlungen am Jahresende; Jahr 0 = Nettoinvestition. Jahreswasserprofil wiederholt sich ohne Wachstum der Nutzerzahl.
A6: Jahr | B6: Einsparmenge m³ | C6: Vermiedene Kosten € | D6: Betriebskosten € | E6: Ersatzinvestition € | F6: Restwert € | G6: Cashflow € | H6: Diskontfaktor | I6: Barwert CF € | J6: Kumuliert diskontiert € | K6: Barwert Kosten € | L6: Barwert Einsparmenge m³ | M6: Erste Rückgewinnung Jahr
A7: 0 | B7: =0 -> 0 | C7: =0 -> 0 | D7: =0 -> 0 | E7: =Berechnung!$B$14 -> 25000 | F7: =0 -> 0 | G7: =-E7 -> -25000 | H7: =1 -> 1 | I7: =G7 -> -25000 | J7: =I7 -> -25000 | K7: =E7 -> 25000 | L7: =0 -> 0 | M7: =""
A8: 1 | B8: =IF(AND(A8<=Eingaben!$B$11,Prüfungen!$B$4=0),Berechnung!$B$10,0) -> 555.38976 | C8: =IFERROR(IF(AND(A8<=Eingaben!$B$11,Prüfungen!$B$4=0),B8*(Eingaben!$B$36*(1+Eingaben!$B$40)^(A8-1)+Eingaben!$B$37*Eingaben!$B$38*(1+Eingaben!$B$46)^(A8-1)),0),0) -> 1388.4744 | D8: =IFERROR(IF(AND(A8<=Eingaben!$B$11,Prüfungen!$B$4=0),(Eingaben!$B$32+Eingaben!$B$35)*(1+Eingaben!$B$41)^(A8-1)+Berechnung!$B$15*Eingaben!$B$34*(1+Eingaben!$B$42)^(A8-1),0),0) -> 781.527 | E8: =IFERROR(IF(AND(AND(A8<=Eingaben!$B$11,Prüfungen!$B$4=0),A8=Eingaben!$B$43),Eingaben!$B$44*(1+Eingaben!$B$41)^(A8-1),0),0) -> 0 | F8: =IFERROR(IF(AND(AND(A8<=Eingaben!$B$11,Prüfungen!$B$4=0),A8=Eingaben!$B$11),Eingaben!$B$45,0),0) -> 0 | G8: =C8-D8-E8+F8 -> 606.94739 | H8: =IFERROR(IF(AND(A8<=Eingaben!$B$11,Prüfungen!$B$4=0),1/(1+Eingaben!$B$39)^A8,0),0) -> 0.97087379 | I8: =G8*H8 -> 589.26931 | J8: =J7+I8 -> -24410.731 | K8: =(D8+E8-F8)*H8 -> 758.76408 | L8: =B8*H8 -> 539.21336 | M8: =IF(AND(AND(A8<=Eingaben!$B$11,Prüfungen!$B$4=0),Berechnung!$B$14>0,J7<0,J8>=0,I8>0),A8-1-J7/I8,"")
A9: 2 | B9: =IF(AND(A9<=Eingaben!$B$11,Prüfungen!$B$4=0),Berechnung!$B$10,0) -> 555.38976 | C9: =IFERROR(IF(AND(A9<=Eingaben!$B$11,Prüfungen!$B$4=0),B9*(Eingaben!$B$36*(1+Eingaben!$B$40)^(A9-1)+Eingaben!$B$37*Eingaben!$B$38*(1+Eingaben!$B$46)^(A9-1)),0),0) -> 1416.2439 | D9: =IFERROR(IF(AND(A9<=Eingaben!$B$11,Prüfungen!$B$4=0),(Eingaben!$B$32+Eingaben!$B$35)*(1+Eingaben!$B$41)^(A9-1)+Berechnung!$B$15*Eingaben!$B$34*(1+Eingaben!$B$42)^(A9-1),0),0) -> 797.15754 | E9: =IFERROR(IF(AND(AND(A9<=Eingaben!$B$11,Prüfungen!$B$4=0),A9=Eingaben!$B$43),Eingaben!$B$44*(1+Eingaben!$B$41)^(A9-1),0),0) -> 0 | F9: =IFERROR(IF(AND(AND(A9<=Eingaben!$B$11,Prüfungen!$B$4=0),A9=Eingaben!$B$11),Eingaben!$B$45,0),0) -> 0 | G9: =C9-D9-E9+F9 -> 619.08634 | H9: =IFERROR(IF(AND(A9<=Eingaben!$B$11,Prüfungen!$B$4=0),1/(1+Eingaben!$B$39)^A9,0),0) -> 0.94259591 | I9: =G9*H9 -> 583.54825 | J9: =J8+I9 -> -23827.182 | K9: =(D9+E9-F9)*H9 -> 751.39744 | L9: =B9*H9 -> 523.50811 | M9: =IF(AND(AND(A9<=Eingaben!$B$11,Prüfungen!$B$4=0),Berechnung!$B$14>0,J8<0,J9>=0,I9>0),A9-1-J8/I9,"")
